<?xml version="1.0" encoding="utf-8"?>
<!-- This URDF was automatically created by SolidWorks to URDF Exporter! Originally created by Stephen Brawner (brawner@gmail.com) 
     Commit Version: 1.6.0-1-g15f4949  Build Version: 1.6.7594.29634
     For more information, please see http://wiki.ros.org/sw_urdf_exporter -->
<robot
  name="robot_description">
  <link name="base_footprint">
  </link>
    <joint name="base_link_joint" type="fixed">
      <origin xyz="0 0 0.34" rpy="0 0 0" />
    <parent link="base_footprint"/>
    <child link="base_link" />
  </joint>
  <link
    name="base_link">
    <inertial>
      <origin
        xyz="-0.15914 -9.5967E-05 0.10539"
        rpy="0 0 0" />
      <mass
        value="12.06" />
      <inertia
        ixx="0.10838"
        ixy="0.0001198"
        ixz="-0.0012052"
        iyy="0.25068"
        iyz="0.00021772"
        izz="0.32193" />
    </inertial>
    <visual>
      <origin
        xyz="0 0 0"
        rpy="0 0 0" />
      <geometry>
        <mesh
          filename="package://robot_description/meshes/base_link.STL" />
      </geometry>
      <material
        name="">
        <color
          rgba="0.75294 0.75294 0.75294 1" />
      </material>
    </visual>
    <collision>
      <origin
        xyz="0 0 0"
        rpy="0 0 0" />
      <geometry>
        <mesh
          filename="package://robot_description/meshes/base_link.STL" />
      </geometry>
    </collision>
  </link>
  <link
    name="fl_yaw_link">
    <inertial>
      <origin
        xyz="-0.27952 0.23806 0.44611"
        rpy="0 0 0" />
      <mass
        value="30.507" />
      <inertia
        ixx="1.6554"
        ixy="-0.02242"
        ixz="-0.47837"
        iyy="2.9139"
        iyz="-0.021024"
        izz="2.3338" />
    </inertial>
    <visual>
      <origin
        xyz="0 0 0"
        rpy="0 0 0" />
      <geometry>
        <mesh
          filename="package://robot_description/meshes/fl_yaw_link.STL" />
      </geometry>
      <material
        name="">
        <color
          rgba="1 1 1 1" />
      </material>
    </visual>
    <collision>
      <origin
        xyz="0 0 0"
        rpy="0 0 0" />
      <geometry>
        <mesh
          filename="package://robot_description/meshes/fl_yaw_link.STL" />
      </geometry>
    </collision>
  </link>
  <joint
    name="fl_yaw_joint"
    type="revolute">
    <origin
      xyz="0.3205 -0.234 -0.1754"
      rpy="0 0 0" />
    <parent
      link="base_link" />
    <child
      link="fl_yaw_link" />
    <axis
      xyz="0 0 -1" />
    <limit
      lower="-0.516"
      upper="0.516"
      effort="0"
      velocity="0" />
  </joint>
  <link
    name="fl_wheel_link">
    <inertial>
      <origin
        xyz="-0.27952 0.28606 0.44611"
        rpy="0 0 0" />
      <mass
        value="30.507" />
      <inertia
        ixx="1.6554"
        ixy="-0.02242"
        ixz="-0.47837"
        iyy="2.9139"
        iyz="-0.021024"
        izz="2.3338" />
    </inertial>
    <visual>
      <origin
        xyz="0 0 0"
        rpy="0 0 0" />
      <geometry>
        <mesh
          filename="package://robot_description/meshes/fl_wheel_link.STL" />
      </geometry>
      <material
        name="">
        <color
          rgba="1 1 1 1" />
      </material>
    </visual>
    <collision>
      <origin
        xyz="0 0 0"
        rpy="0 0 0" />
      <geometry>
        <mesh
          filename="package://robot_description/meshes/fl_wheel_link.STL" />
      </geometry>
    </collision>
  </link>
  <joint
    name="fl_wheel_joint"
    type="continuous">
    <origin
      xyz="0 -0.048 0"
      rpy="0 0 0" />
    <parent
      link="fl_yaw_link" />
    <child
      link="fl_wheel_link" />
    <axis
      xyz="0 1 0" />
  </joint>
  <link
    name="fr_yaw_link">
    <inertial>
      <origin
        xyz="-0.279521156342373 -0.229938561780429 0.44610688424323"
        rpy="0 0 0" />
      <mass
        value="30.5066266511579" />
      <inertia
        ixx="1.65541542845514"
        ixy="-0.0224203982987276"
        ixz="-0.478365539826021"
        iyy="2.91389154857164"
        iyz="-0.0210240992622669"
        izz="2.33380384946737" />
    </inertial>
    <visual>
      <origin
        xyz="0 0 0"
        rpy="0 0 0" />
      <geometry>
        <mesh
          filename="package://robot_description/meshes/fr_yaw_link.STL" />
      </geometry>
      <material
        name="">
        <color
          rgba="1 1 1 1" />
      </material>
    </visual>
    <collision>
      <origin
        xyz="0 0 0"
        rpy="0 0 0" />
      <geometry>
        <mesh
          filename="package://robot_description/meshes/fr_yaw_link.STL" />
      </geometry>
    </collision>
  </link>
  <joint
    name="fr_yaw_joint"
    type="revolute">
    <origin
      xyz="0.3205 0.234 -0.1754"
      rpy="0 0 0" />
    <parent
      link="base_link" />
    <child
      link="fr_yaw_link" />
    <axis
      xyz="0 0 1" />
    <limit
      lower="-0.516"
      upper="0.516"
      effort="0"
      velocity="0" />
  </joint>
  <link
    name="fr_wheel_link">
    <inertial>
      <origin
        xyz="-0.27952115634236 -0.277938561780588 0.446106884243232"
        rpy="0 0 0" />
      <mass
        value="30.5066266511579" />
      <inertia
        ixx="1.65541542845513"
        ixy="-0.0224203982987281"
        ixz="-0.478365539826021"
        iyy="2.91389154857164"
        iyz="-0.0210240992622671"
        izz="2.33380384946737" />
    </inertial>
    <visual>
      <origin
        xyz="0 0 0"
        rpy="0 0 0" />
      <geometry>
        <mesh
          filename="package://robot_description/meshes/fr_wheel_link.STL" />
      </geometry>
      <material
        name="">
        <color
          rgba="1 1 1 1" />
      </material>
    </visual>
    <collision>
      <origin
        xyz="0 0 0"
        rpy="0 0 0" />
      <geometry>
        <mesh
          filename="package://robot_description/meshes/fr_wheel_link.STL" />
      </geometry>
    </collision>
  </link>
  <joint
    name="fr_wheel_joint"
    type="continuous">
    <origin
      xyz="0 0.048 0"
      rpy="0 0 0" />
    <parent
      link="fr_yaw_link" />
    <child
      link="fr_wheel_link" />
    <axis
      xyz="0 -1 0" />
  </joint>
  <link
    name="bl_wheel_link">
    <inertial>
      <origin
        xyz="0.371988324955183 0.286061438219423 0.446274637839659"
        rpy="0 0 0" />
      <mass
        value="30.5066266511579" />
      <inertia
        ixx="1.65541542845513"
        ixy="-0.0224203982987291"
        ixz="-0.478365539826021"
        iyy="2.91389154857164"
        iyz="-0.0210240992622676"
        izz="2.33380384946737" />
    </inertial>
    <visual>
      <origin
        xyz="0 0 0"
        rpy="0 0 0" />
      <geometry>
        <mesh
          filename="package://robot_description/meshes/bl_wheel_link.STL" />
      </geometry>
      <material
        name="">
        <color
          rgba="1 1 1 1" />
      </material>
    </visual>
    <collision>
      <origin
        xyz="0 0 0"
        rpy="0 0 0" />
      <geometry>
        <mesh
          filename="package://robot_description/meshes/bl_wheel_link.STL" />
      </geometry>
    </collision>
  </link>
  <joint
    name="bl_wheel_joint"
    type="continuous">
    <origin
      xyz="-0.33101 -0.282 -0.17557"
      rpy="0 0 0" />
    <parent
      link="base_link" />
    <child
      link="bl_wheel_link" />
    <axis
      xyz="0 1 0" />
  </joint>
  <link
    name="br_wheel_link">
    <inertial>
      <origin
        xyz="0.371978843657749 -0.277938561780588 0.446206884243225"
        rpy="0 0 0" />
      <mass
        value="30.5066266511579" />
      <inertia
        ixx="1.65541542845513"
        ixy="-0.0224203982987279"
        ixz="-0.478365539826018"
        iyy="2.91389154857164"
        iyz="-0.021024099262267"
        izz="2.33380384946738" />
    </inertial>
    <visual>
      <origin
        xyz="0 0 0"
        rpy="0 0 0" />
      <geometry>
        <mesh
          filename="package://robot_description/meshes/br_wheel_link.STL" />
      </geometry>
      <material
        name="">
        <color
          rgba="1 1 1 1" />
      </material>
    </visual>
    <collision>
      <origin
        xyz="0 0 0"
        rpy="0 0 0" />
      <geometry>
        <mesh
          filename="package://robot_description/meshes/br_wheel_link.STL" />
      </geometry>
    </collision>
  </link>
  <joint
    name="br_wheel_joint"
    type="continuous">
    <origin
      xyz="-0.331 0.282 -0.1755"
      rpy="0 0 0" />
    <parent
      link="base_link" />
    <child
      link="br_wheel_link" />
    <axis
      xyz="0 -1 0" />
  </joint>
  <link
    name="cloud_base_link">
    <inertial>
      <origin
        xyz="-0.00107056668814468 0.000355883793422292 0.0294178572049006"
        rpy="0 0 0" />
      <mass
        value="2.79967245417279" />
      <inertia
        ixx="0.0218041333220011"
        ixy="0.000149445024526007"
        ixz="-5.4588855827757E-05"
        iyy="0.0212664972862997"
        iyz="7.12806969594676E-05"
        izz="0.0292577352544243" />
    </inertial>
    <visual>
      <origin
        xyz="0 0 0"
        rpy="0 0 0" />
      <geometry>
        <mesh
          filename="package://robot_description/meshes/cloud_base_link.STL" />
      </geometry>
      <material
        name="">
        <color
          rgba="1 1 1 1" />
      </material>
    </visual>
    <collision>
      <origin
        xyz="0 0 0"
        rpy="0 0 0" />
      <geometry>
        <mesh
          filename="package://robot_description/meshes/cloud_base_link.STL" />
      </geometry>
    </collision>
  </link>
  <joint
    name="cloud_base_joint"
    type="fixed">
    <origin
      xyz="0.195 0 0.139"
      rpy="0 0 0" />
    <parent
      link="base_link" />
    <child
      link="cloud_base_link" />
    <axis
      xyz="0 0 0" />
  </joint>
  <link
    name="cloud_yaw_link">
    <inertial>
      <origin
        xyz="3.82843478863304E-08 2.98602090883249E-06 -0.00102621290249716"
        rpy="0 0 0" />
      <mass
        value="7.2831368849384" />
      <inertia
        ixx="0.0910347461613076"
        ixy="-1.06880079285815E-08"
        ixz="-7.73754816038974E-09"
        iyy="0.0905154171805842"
        iyz="-6.87608760454308E-07"
        izz="0.0248026922778621" />
    </inertial>
    <visual>
      <origin
        xyz="0 0 0"
        rpy="0 0 0" />
      <geometry>
        <mesh
          filename="package://robot_description/meshes/cloud_yaw_link.STL" />
      </geometry>
      <material
        name="">
        <color
          rgba="1 1 1 1" />
      </material>
    </visual>
    <collision>
      <origin
        xyz="0 0 0"
        rpy="0 0 0" />
      <geometry>
        <mesh
          filename="package://robot_description/meshes/cloud_yaw_link.STL" />
      </geometry>
    </collision>
  </link>
  <joint
    name="cloud_yaw_joint"
    type="continuous">
    <origin
      xyz="0 0 0.278"
      rpy="0 0 0" />
    <parent
      link="cloud_base_link" />
    <child
      link="cloud_yaw_link" />
    <axis
      xyz="0 0 1" />
    <limit
      lower="-3.1415926535"
      upper="3.1415926535"
      effort="0"
      velocity="0" />
  </joint>
  <link
    name="cloud_pitch_link">
    <inertial>
      <origin
        xyz="0.00250575362899488 0.0192527925750246 -0.00483033515548448"
        rpy="0 0 0" />
      <mass
        value="6.44269178931367" />
      <inertia
        ixx="0.211461209470067"
        ixy="-0.00402266404388985"
        ixz="-0.00067904988645607"
        iyy="0.0483449961927441"
        iyz="0.00701921938246433"
        izz="0.230859876365758" />
    </inertial>
    <visual>
      <origin
        xyz="0 0 0"
        rpy="0 0 0" />
      <geometry>
        <mesh
          filename="package://robot_description/meshes/cloud_pitch_link.STL" />
      </geometry>
      <material
        name="">
        <color
          rgba="1 1 1 1" />
      </material>
    </visual>
    <collision>
      <origin
        xyz="0 0 0"
        rpy="0 0 0" />
      <geometry>
        <mesh
          filename="package://robot_description/meshes/cloud_pitch_link.STL" />
      </geometry>
    </collision>
  </link>
  <joint
    name="cloud_pitch_joint"
    type="revolute">
    <origin
      xyz="0 0 0.0305"
      rpy="0 0 0" />
    <parent
      link="cloud_yaw_link" />
    <child
      link="cloud_pitch_link" />
    <axis
      xyz="0 1 0" />
    <limit
      lower="-1.570796"
      upper="1.570796"
      effort="0"
      velocity="0" />
  </joint>
  <link
    name="laser_base_link">
    <inertial>
      <origin
        xyz="2.23091641826656E-08 1.20787168066745E-06 0.00529776059381226"
        rpy="0 0 0" />
      <mass
        value="0.052040899906715" />
      <inertia
        ixx="4.37341983251945E-05"
        ixy="-3.14276320789944E-11"
        ixz="1.3813453733048E-11"
        iyy="1.73099215842761E-05"
        iyz="-4.77286692727187E-11"
        izz="5.90231425644455E-05" />
    </inertial>
    <visual>
      <origin
        xyz="0 0 0"
        rpy="0 0 0" />
      <geometry>
        <mesh
          filename="package://robot_description/meshes/laser_base_link.STL" />
      </geometry>
      <material
        name="">
        <color
          rgba="0.380392156862745 0.525490196078431 1 1" />
      </material>
    </visual>
    <collision>
      <origin
        xyz="0 0 0"
        rpy="0 0 0" />
      <geometry>
        <mesh
          filename="package://robot_description/meshes/laser_base_link.STL" />
      </geometry>
    </collision>
  </link>
  <joint
    name="laser_base_joint"
    type="fixed">
    <origin
      xyz="0.512 0 -0.177"
      rpy="0 0 0" />
    <parent
      link="base_link" />
    <child
      link="laser_base_link" />
    <axis
      xyz="0 0 0" />
  </joint>
  <link
    name="laser_link">
    <inertial>
      <origin
        xyz="0 5.01675115346061E-19 0.0188690531467447"
        rpy="0 0 0" />
      <mass
        value="0.168315967042029" />
      <inertia
        ixx="7.91781165894466E-05"
        ixy="-2.84343335565089E-22"
        ixz="1.0929502709567E-20"
        iyy="7.91781165894466E-05"
        iyz="4.20303190579889E-22"
        izz="0.000117542170683099" />
    </inertial>
    <visual>
      <origin
        xyz="0 0 0"
        rpy="0 0 0" />
      <geometry>
        <mesh
          filename="package://robot_description/meshes/laser_link.STL" />
      </geometry>
      <material
        name="">
        <color
          rgba="0 0 0 1" />
      </material>
    </visual>
    <collision>
      <origin
        xyz="0 0 0"
        rpy="0 0 0" />
      <geometry>
        <mesh
          filename="package://robot_description/meshes/laser_link.STL" />
      </geometry>
    </collision>
  </link>
  <joint
    name="laser_joint"
    type="fixed">
    <origin
      xyz="0 0 0.008"
      rpy="0 0 0" />
    <parent
      link="laser_base_link" />
    <child
      link="laser_link" />
    <axis
      xyz="0 0 0" />
  </joint>
  <link
    name="valodyne_base_link">
    <inertial>
      <origin
        xyz="-0.000127176303653165 2.31859873638434E-07 -0.0449383971949976"
        rpy="0 0 0" />
      <mass
        value="0.376994643906441" />
      <inertia
        ixx="0.0118542542856136"
        ixy="3.70901498526542E-10"
        ixz="2.18083625889328E-06"
        iyy="0.0118542554278508"
        iyz="-1.07060477987536E-08"
        izz="0.00163430081592151" />
    </inertial>
    <visual>
      <origin
        xyz="0 0 0"
        rpy="0 0 0" />
      <geometry>
        <mesh
          filename="package://robot_description/meshes/valodyne_base_link.STL" />
      </geometry>
      <material
        name="">
        <color
          rgba="1 1 1 1" />
      </material>
    </visual>
    <collision>
      <origin
        xyz="0 0 0"
        rpy="0 0 0" />
      <geometry>
        <mesh
          filename="package://robot_description/meshes/valodyne_base_link.STL" />
      </geometry>
    </collision>
  </link>
  <joint
    name="valodyne_base_joint"
    type="fixed">
    <origin
      xyz="-0.195 0 0.441"
      rpy="0 0 0" />
    <parent
      link="base_link" />
    <child
      link="valodyne_base_link" />
    <axis
      xyz="0 0 0" />
  </joint>
  <link
    name="valodyne_link">
    <inertial>
      <origin
        xyz="0 -1.35321723598849E-19 0.0399025566772944"
        rpy="0 0 0" />
      <mass
        value="0.69098907548352" />
      <inertia
        ixx="0.00084186513081361"
        ixy="-7.34095220953727E-21"
        ixz="1.70617759083443E-20"
        iyy="0.00084186513081361"
        iyz="-1.04039849302502E-21"
        izz="0.000950078684047923" />
    </inertial>
    <visual>
      <origin
        xyz="0 0 0"
        rpy="0 0 0" />
      <geometry>
        <mesh
          filename="package://robot_description/meshes/valodyne_link.STL" />
      </geometry>
      <material
        name="">
        <color
          rgba="0.0823529411764706 0.6 1 1" />
      </material>
    </visual>
    <collision>
      <origin
        xyz="0 0 0"
        rpy="0 0 0" />
      <geometry>
        <mesh
          filename="package://robot_description/meshes/valodyne_link.STL" />
      </geometry>
    </collision>
  </link>
  <joint
    name="valodyne_joint"
    type="continuous">
    <origin
      xyz="0 0 0.209"
      rpy="0 0 0" />
    <parent
      link="valodyne_base_link" />
    <child
      link="valodyne_link" />
    <axis
      xyz="0 0 1" />
  </joint>
</robot>